{"trial_id": "0000", "hyperparameters": {"space": [{"class_name": "Choice", "config": {"name": "conv_layers", "default": 3, "conditions": [], "values": [3, 4, 5], "ordered": true}}, {"class_name": "Choice", "config": {"name": "conv_filters", "default": 8, "conditions": [], "values": [8, 16, 32], "ordered": true}}, {"class_name": "Choice", "config": {"name": "dropout_rate", "default": 0.1, "conditions": [], "values": [0.1, 0.3, 0.2], "ordered": true}}, {"class_name": "Choice", "config": {"name": "dense_depth", "default": 1, "conditions": [], "values": [1, 2, 3], "ordered": true}}], "values": {"conv_layers": 5, "conv_filters": 16, "dropout_rate": 0.3, "dense_depth": 3}}, "metrics": {"metrics": {}}, "score": null, "best_step": 0, "status": "FAILED", "message": "Traceback (most recent call last):\n  File \"C:\\Users\\nicco\\tensorflow_env\\Lib\\site-packages\\keras_tuner\\src\\engine\\base_tuner.py\", line 274, in _try_run_and_update_trial\n    self._run_and_update_trial(trial, *fit_args, **fit_kwargs)\n  File \"C:\\Users\\nicco\\tensorflow_env\\Lib\\site-packages\\keras_tuner\\src\\engine\\base_tuner.py\", line 239, in _run_and_update_trial\n    results = self.run_trial(trial, *fit_args, **fit_kwargs)\n              ^^^^^^^^^^^^^^^^^^^^^^^^^^^^^^^^^^^^^^^^^^^^^^\n  File \"C:\\Users\\nicco\\tensorflow_env\\Lib\\site-packages\\keras_tuner\\src\\engine\\tuner.py\", line 314, in run_trial\n    obj_value = self._build_and_fit_model(trial, *args, **copied_kwargs)\n                ^^^^^^^^^^^^^^^^^^^^^^^^^^^^^^^^^^^^^^^^^^^^^^^^^^^^^^^^\n  File \"C:\\Users\\nicco\\tensorflow_env\\Lib\\site-packages\\keras_tuner\\src\\engine\\tuner.py\", line 233, in _build_and_fit_model\n    results = self.hypermodel.fit(hp, model, *args, **kwargs)\n              ^^^^^^^^^^^^^^^^^^^^^^^^^^^^^^^^^^^^^^^^^^^^^^^\n  File \"C:\\Users\\nicco\\tensorflow_env\\Lib\\site-packages\\keras_tuner\\src\\engine\\hypermodel.py\", line 149, in fit\n    return model.fit(*args, **kwargs)\n           ^^^^^^^^^^^^^^^^^^^^^^^^^^\n  File \"C:\\Users\\nicco\\tensorflow_env\\Lib\\site-packages\\keras\\src\\utils\\traceback_utils.py\", line 122, in error_handler\n    raise e.with_traceback(filtered_tb) from None\n  File \"C:\\Users\\nicco\\tensorflow_env\\Lib\\site-packages\\keras\\src\\utils\\traceback_utils.py\", line 124, in error_handler\n    del filtered_tb\n        ^^^^^^^^^^^\nValueError: Exception encountered when calling MaxPooling2D.call().\n\n\u001b[1mNegative dimension size caused by subtracting 4 from 1 for '{{node functional_1/max_pooling2d_4_1/MaxPool2d}} = MaxPool[T=DT_FLOAT, data_format=\"NHWC\", explicit_paddings=[], ksize=[1, 4, 4, 1], padding=\"VALID\", strides=[1, 4, 4, 1]](functional_1/batch_normalization_4_1/batchnorm/add_1)' with input shapes: [?,1,1,80].\u001b[0m\n\nArguments received by MaxPooling2D.call():\n  \u2022 inputs=tf.Tensor(shape=(None, 1, 1, 80), dtype=float32)\n"}